<?xml version='1.0' ?>

<sdf version='1.4'>
    <model name="No_name">
        

        <!-- MODEL -->


        <link name="chassis">
            <pose>0 0 0.0175 0 0 0</pose>
            <inertial>
                <pose>0 0.006896 0.111428 0 0 0</pose>
                <mass>14.5</mass>
                <inertia>
                    <ixx>0.664203113</ixx>
                    <iyy>0.604736499</iyy>
                    <izz>1.075415484</izz>
                </inertia>
            </inertial>
            <collision name="collision">
                <geometry>
                    <mesh>
                        <uri>file://{PATH_TO_MODELS}/models/noname/meshes/chassis.stl</uri>
                    </mesh>
                </geometry>
            </collision>
            <visual name="visual">
                <geometry>
                    <mesh>
                        <uri>file://{PATH_TO_MODELS}/models/noname/meshes/chassis.stl</uri>
                    </mesh>
                </geometry>
            </visual>

            <collision name="left_plate_collision">
            <pose>0.263 0.263 0.0265 0 0 0</pose>
                <geometry>
                    <cylinder>
                        <radius>.0215</radius>
                        <length>.016</length>
                    </cylinder>
                </geometry>
            </collision>
            <visual name="left_plate_visual">
            <pose>0.263 0.263 0.0265 0 0 0</pose>
                <geometry>
                    <cylinder>
                        <radius>.0215</radius>
                        <length>.016</length>
                    </cylinder>
                </geometry>
            </visual>

            <collision name="right_plate_collision">
            <pose>0.263 -0.263 0.0265 0 0 0</pose>
                <geometry>
                    <cylinder>
                        <radius>.0215</radius>
                        <length>.016</length>
                    </cylinder>
                </geometry>
            </collision>
            <visual name="right_plate_visual">
            <pose>0.263 -0.263 0.0265 0 0 0</pose>
                <geometry>
                    <cylinder>
                        <radius>.0215</radius>
                        <length>.016</length>
                    </cylinder>
                </geometry>
            </visual>

            <collision name="right_sphere_collision">
                <pose>0.262 -0.263 0.0005 1.5707 0 0</pose>
                <geometry>
                    <sphere>
                        <radius>.018</radius>
                    </sphere>
                </geometry>
                <surface>
                    <friction>
                        <ode>
                            <mu>0</mu>
                            <mu2>0</mu2>
                        </ode>
                    </friction>
                </surface>
            </collision>
            <visual name="right_sphere_visual">
                <pose>0.262 -0.263 0.0005 1.5707 0 0</pose>
                <geometry>
                    <sphere>
                        <radius>.018</radius>
                    </sphere>
                </geometry>
            </visual>

            <collision name="left_sphere_collision">
                <pose>0.262 0.263 0.0005 1.5707 0 0</pose>
                <geometry>
                    <sphere>
                        <radius>.018</radius>
                    </sphere>
                </geometry>
                <surface>
                    <friction>
                        <ode>
                            <mu>0</mu>
                            <mu2>0</mu2>
                        </ode>
                    </friction>
                </surface>
            </collision>
            <visual name="left_sphere_visual">
                <pose>0.262 0.263 0.0005 1.5707 0 0</pose>
                <geometry>
                    <sphere>
                        <radius>.018</radius>
                    </sphere>
                </geometry>
            </visual>

            <!--<sensor name="laser" type="ray">
                <pose>0.17 0 0.136 0 0 0</pose>
                <ray>
                    <scan>
                        <horizontal>
                            <samples>640</samples>
                            <resolution>1</resolution>
                            <min_angle>-1.020</min_angle>
                            <max_angle>1.020</max_angle>
                        </horizontal>
                    </scan>
                    <range>
                        <min>0.25</min>
                        <max>10</max>
                        <resolution>0.01</resolution>
                    </range>
                </ray>
                <plugin name="laser" filename="libRayPlugin.so"/>
                <always_on>1</always_on>
                <update_rate>30</update_rate>
                <visualize>true</visualize>
            </sensor>-->
        </link>

        <link name="right_back_wheel">
            <inertial>
                <mass>1.8</mass>
            </inertial>
            <pose>-0.175 -0.27 0.1 1.5707 0 0</pose>
            <collision name="collision">
                <geometry>
                    <cylinder>
                        <radius>.1</radius>
                        <length>.05</length>
                    </cylinder>
                </geometry>
                <surface>
                    <friction>
                        <ode>
                            <mu>1000000</mu>
                            <mu2>1000000</mu2>
                        </ode>
                    </friction>
                </surface>
            </collision>
            <visual name="visual">
                <geometry>
                    <cylinder>
                        <radius>.1</radius>
                        <length>.05</length>
                    </cylinder>
                </geometry>
            </visual>
        </link>

        <link name="left_back_wheel">
            <inertial>
                <mass>1.8</mass>
            </inertial>
            <pose>-0.175 0.27 0.1 1.5707 0 0</pose> 
            <collision name="collision">
                <geometry>
                    <cylinder>
                        <radius>.1</radius>
                        <length>.05</length>
                    </cylinder>
                </geometry>
                <surface>
                    <friction>
                        <ode>
                            <mu>1000000</mu>
                            <mu2>1000000</mu2>
                        </ode>
                    </friction>
                </surface>
            </collision>
            <visual name="visual">
                <geometry>
                    <cylinder>
                        <radius>.1</radius>
                        <length>.05</length>
                    </cylinder>
                </geometry>
            </visual>
        </link>


        <!-- JOINTS -->


        <joint type="revolute" name="right_back_wheel_hinge">
            <child>right_back_wheel</child>
            <parent>chassis</parent>
            <axis>
                <xyz>0 1 0</xyz>
            </axis>
        </joint>

        <joint type="revolute" name="left_back_wheel_hinge">
            <child>left_back_wheel</child>
            <parent>chassis</parent>
            <axis>
                <xyz>0 1 0</xyz>
            </axis>
        </joint>


        <!-- PLUGINS -->


        <plugin name="differential_drive_controller" filename="libgazebo_ros_diff_drive.so">
            <legacyMode>false</legacyMode>
            <alwaysOn>true</alwaysOn>
            <updateRate>20</updateRate>
            <leftJoint>left_back_wheel_hinge</leftJoint>
            <rightJoint>right_back_wheel_hinge</rightJoint>
            <wheelSeparation>0.54</wheelSeparation>
            <wheelDiameter>0.2</wheelDiameter>
            <wheelTorque>20</wheelTorque>
            <commandTopic>/cmd_vel</commandTopic>
            <odometryTopic>odom</odometryTopic>
            <odometryFrame>odom</odometryFrame>
            <publishTf>1</publishTf>
            <publishWheelJointState>true</publishWheelJointState>
            <robotBaseFrame>base_footprint</robotBaseFrame>
        </plugin>

        <plugin name="gazebo_speed_sensor_plugin" filename="libgazebo_speed_sensor_plugin.so"/>

    </model>
</sdf>